Workbook

Sheet rekap absensi seluruhnya
E1: PEMERINTAH PROVINSI JAWA TIMUR
E2: DINAS PENDIDIKAN
E3: SEKOLAH MENENGAH ATAS NEGERI 21 SURABAYA
E4: Jl. Argopuro 11-15 Surabaya Telp. 031-5350753 Fax. 031-5341530
E6: DAFTAR KETERLAMBATAN SISWA
E7: ="Tahun Pelajaran "&MID(D12,3,9) -> #REF!
A12: Tahun Pelajaran | D12: =": "&INDIRECT("'Data Murid'!A3") -> #REF!
A14: NO | C14: NAMA LENGKAP | D14: JK | E14: ="JULI "&LEFT(MID(D12,3,9),4) -> #REF! | F14: ="AGUSTUS "&LEFT(MID(D12,3,9),4) -> #REF! | G14: ="SEPTEMBER "&LEFT(MID(D12,3,9),4) -> #REF! | H14: ="OKTOBER "&LEFT(MID(D12,3,9),4) -> #REF! | I14: ="NOVEMBER "&LEFT(MID(D12,3,9),4) -> #REF! | J14: ="DESEMBER "&LEFT(MID(D12,3,9),4) -> #REF! | K14: JUMLAH SEMESTER 1 | M14: ="JANUARI "&RIGHT(MID(D12,3,9),4) -> #REF! | N14: ="FEBRUARI "&RIGHT(MID(D12,3,9),4) -> #REF! | O14: ="MARET "&RIGHT(MID(D12,3,9),4) -> #REF! | P14: ="APRIL "&RIGHT(MID(D12,3,9),4) -> #REF! | Q14: ="MEI "&RIGHT(MID(D12,3,9),4) -> #REF! | R14: ="JUNI "&RIGHT(MID(D12,3,9),4) -> #REF! | S14: JUMLAH SEMESTER 2 | T14: JUMLAH AKUMULASI 2 SEMESTER
A16: Urut | B16: NIS
E17: H | F17: H | G17: H | H17: H | I17: H | J17: H | K17: H | M17: H | N17: H | O17: H | P17: H | Q17: H | R17: H | S17: H | T17: H
A19: {=INDIRECT("'Data Murid'!A" & ROW(A5)) & " " & INDIRECT("'Data Murid'!A" & ROW(A6))} -> #REF!
A20: 1 | B20: =IF(INDIRECT("'Data Murid'!B" & ROW(A8))="", "", INDIRECT("'Data Murid'!B" & ROW(A8))) -> #REF! | C20: =IF(INDIRECT("'Data Murid'!C" & ROW(B8))="", "", INDIRECT("'Data Murid'!C" & ROW(B8))) -> #REF! | D20: =IF(INDIRECT("'Data Murid'!D" & ROW(C8))="", "", LEFT(INDIRECT("'Data Murid'!D" & ROW(C8)),1)) -> #REF! | E20: =Jul!AJ15 -> 0 | F20: =Ags!AJ15 -> 0 | G20: =Sep!AJ15 -> 0 | H20: =Okt!AJ15 -> 0 | I20: =Nov!AJ15 -> 0 | J20: =Des!AJ15 -> 0 | K20: =SUM(E20:J20) -> 0 | M20: =Jan!AJ15 -> 0 | N20: =Feb!AJ15 -> 0 | O20: =Mar!AJ15 -> 0 | P20: =Apr!AJ15 -> 0 | Q20: =Mei!AJ15 -> 0 | R20: =Jun!AJ15 -> 0 | S20: =SUM(M20:R20) -> 0 | T20: =K20+S20 -> 0
A21: 2 | B21: =IF(INDIRECT("'Data Murid'!B" & ROW(A9))="", "", INDIRECT("'Data Murid'!B" & ROW(A9))) -> #REF! | C21: =IF(INDIRECT("'Data Murid'!C" & ROW(B9))="", "", INDIRECT("'Data Murid'!C" & ROW(B9))) -> #REF! | D21: =IF(INDIRECT("'Data Murid'!D" & ROW(C9))="", "", LEFT(INDIRECT("'Data Murid'!D" & ROW(C9)),1)) -> #REF! | E21: =Jul!AJ16 -> 0 | F21: =Ags!AJ16 -> 0 | G21: =Sep!AJ16 -> 0 | H21: =Okt!AJ16 -> 0 | I21: =Nov!AJ16 -> 0 | J21: =Des!AJ16 -> 0 | K21: =SUM(E21:J21) -> 0 | M21: =Jan!AJ16 -> 0 | N21: =Feb!AJ16 -> 0 | O21: =Mar!AJ16 -> 0 | P21: =Apr!AJ16 -> 0 | Q21: =Mei!AJ16 -> 0 | R21: =Jun!AJ16 -> 0 | S21: =SUM(M21:R21) -> 0 | T21: =K21+S21 -> 0
A22: 3 | B22: =IF(INDIRECT("'Data Murid'!B" & ROW(A10))="", "", INDIRECT("'Data Murid'!B" & ROW(A10))) -> #REF! | C22: =IF(INDIRECT("'Data Murid'!C" & ROW(B10))="", "", INDIRECT("'Data Murid'!C" & ROW(B10))) -> #REF! | D22: =IF(INDIRECT("'Data Murid'!D" & ROW(C10))="", "", LEFT(INDIRECT("'Data Murid'!D" & ROW(C10)),1)) -> #REF! | E22: =Jul!AJ17 -> 0 | F22: =Ags!AJ17 -> 0 | G22: =Sep!AJ17 -> 0 | H22: =Okt!AJ17 -> 0 | I22: =Nov!AJ17 -> 0 | J22: =Des!AJ17 -> 0 | K22: =SUM(E22:J22) -> 0 | M22: =Jan!AJ17 -> 0 | N22: =Feb!AJ17 -> 0 | O22: =Mar!AJ17 -> 0 | P22: =Apr!AJ17 -> 0 | Q22: =Mei!AJ17 -> 0 | R22: =Jun!AJ17 -> 0 | S22: =SUM(M22:R22) -> 0 | T22: =K22+S22 -> 0
A23: 4 | B23: =IF(INDIRECT("'Data Murid'!B" & ROW(A11))="", "", INDIRECT("'Data Murid'!B" & ROW(A11))) -> #REF! | C23: =IF(INDIRECT("'Data Murid'!C" & ROW(B11))="", "", INDIRECT("'Data Murid'!C" & ROW(B11))) -> #REF! | D23: =IF(INDIRECT("'Data Murid'!D" & ROW(C11))="", "", LEFT(INDIRECT("'Data Murid'!D" & ROW(C11)),1)) -> #REF! | E23: =Jul!AJ18 -> 0 | F23: =Ags!AJ18 -> 0 | G23: =Sep!AJ18 -> 0 | H23: =Okt!AJ18 -> 0 | I23: =Nov!AJ18 -> 0 | J23: =Des!AJ18 -> 0 | K23: =SUM(E23:J23) -> 0 | M23: =Jan!AJ18 -> 0 | N23: =Feb!AJ18 -> 0 | O23: =Mar!AJ18 -> 0 | P23: =Apr!AJ18 -> 0 | Q23: =Mei!AJ18 -> 0 | R23: =Jun!AJ18 -> 0 | S23: =SUM(M23:R23) -> 0 | T23: =K23+S23 -> 0
A24: 5 | B24: =IF(INDIRECT("'Data Murid'!B" & ROW(A12))="", "", INDIRECT("'Data Murid'!B" & ROW(A12))) -> #REF! | C24: =IF(INDIRECT("'Data Murid'!C" & ROW(B12))="", "", INDIRECT("'Data Murid'!C" & ROW(B12))) -> #REF! | D24: =IF(INDIRECT("'Data Murid'!D" & ROW(C12))="", "", LEFT(INDIRECT("'Data Murid'!D" & ROW(C12)),1)) -> #REF! | E24: =Jul!AJ19 -> 0 | F24: =Ags!AJ19 -> 0 | G24: =Sep!AJ19 -> 0 | H24: =Okt!AJ19 -> 0 | I24: =Nov!AJ19 -> 0 | J24: =Des!AJ19 -> 0 | K24: =SUM(E24:J24) -> 0 | M24: =Jan!AJ19 -> 0 | N24: =Feb!AJ19 -> 0 | O24: =Mar!AJ19 -> 0 | P24: =Apr!AJ19 -> 0 | Q24: =Mei!AJ19 -> 0 | R24: =Jun!AJ19 -> 0 | S24: =SUM(M24:R24) -> 0 | T24: =K24+S24 -> 0
A25: 6 | B25: =IF(INDIRECT("'Data Murid'!B" & ROW(A13))="", "", INDIRECT("'Data Murid'!B" & ROW(A13))) -> #REF! | C25: =IF(INDIRECT("'Data Murid'!C" & ROW(B13))="", "", INDIRECT("'Data Murid'!C" & ROW(B13))) -> #REF! | D25: =IF(INDIRECT("'Data Murid'!D" & ROW(C13))="", "", LEFT(INDIRECT("'Data Murid'!D" & ROW(C13)),1)) -> #REF! | E25: =Jul!AJ20 -> 0 | F25: =Ags!AJ20 -> 0 | G25: =Sep!AJ20 -> 0 | H25: =Okt!AJ20 -> 0 | I25: =Nov!AJ20 -> 0 | J25: =Des!AJ20 -> 0 | K25: =SUM(E25:J25) -> 0 | M25: =Jan!AJ20 -> 0 | N25: =Feb!AJ20 -> 0 | O25: =Mar!AJ20 -> 0 | P25: =Apr!AJ20 -> 0 | Q25: =Mei!AJ20 -> 0 | R25: =Jun!AJ20 -> 0 | S25: =SUM(M25:R25) -> 0 | T25: =K25+S25 -> 0
A26: 7 | B26: =IF(INDIRECT("'Data Murid'!B" & ROW(A14))="", "", INDIRECT("'Data Murid'!B" & ROW(A14))) -> #REF! | C26: =IF(INDIRECT("'Data Murid'!C" & ROW(B14))="", "", INDIRECT("'Data Murid'!C" & ROW(B14))) -> #REF! | D26: =IF(INDIRECT("'Data Murid'!D" & ROW(C14))="", "", LEFT(INDIRECT("'Data Murid'!D" & ROW(C14)),1)) -> #REF! | E26: =Jul!AJ21 -> 0 | F26: =Ags!AJ21 -> 0 | G26: =Sep!AJ21 -> 0 | H26: =Okt!AJ21 -> 0 | I26: =Nov!AJ21 -> 0 | J26: =Des!AJ21 -> 0 | K26: =SUM(E26:J26) -> 0 | M26: =Jan!AJ21 -> 0 | N26: =Feb!AJ21 -> 0 | O26: =Mar!AJ21 -> 0 | P26: =Apr!AJ21 -> 0 | Q26: =Mei!AJ21 -> 0 | R26: =Jun!AJ21 -> 0 | S26: =SUM(M26:R26) -> 0 | T26: =K26+S26 -> 0
A27: 8 | B27: =IF(INDIRECT("'Data Murid'!B" & ROW(A15))="", "", INDIRECT("'Data Murid'!B" & ROW(A15))) -> #REF! | C27: =IF(INDIRECT("'Data Murid'!C" & ROW(B15))="", "", INDIRECT("'Data Murid'!C" & ROW(B15))) -> #REF! | D27: =IF(INDIRECT("'Data Murid'!D" & ROW(C15))="", "", LEFT(INDIRECT("'Data Murid'!D" & ROW(C15)),1)) -> #REF! | E27: =Jul!AJ22 -> 0 | F27: =Ags!AJ22 -> 0 | G27: =Sep!AJ22 -> 0 | H27: =Okt!AJ22 -> 0 | I27: =Nov!AJ22 -> 0 | J27: =Des!AJ22 -> 0 | K27: =SUM(E27:J27) -> 0 | M27: =Jan!AJ22 -> 0 | N27: =Feb!AJ22 -> 0 | O27: =Mar!AJ22 -> 0 | P27: =Apr!AJ22 -> 0 | Q27: =Mei!AJ22 -> 0 | R27: =Jun!AJ22 -> 0 | S27: =SUM(M27:R27) -> 0 | T27: =K27+S27 -> 0
A28: 9 | B28: =IF(INDIRECT("'Data Murid'!B" & ROW(A16))="", "", INDIRECT("'Data Murid'!B" & ROW(A16))) -> #REF! | C28: =IF(INDIRECT("'Data Murid'!C" & ROW(B16))="", "", INDIRECT("'Data Murid'!C" & ROW(B16))) -> #REF! | D28: =IF(INDIRECT("'Data Murid'!D" & ROW(C16))="", "", LEFT(INDIRECT("'Data Murid'!D" & ROW(C16)),1)) -> #REF! | E28: =Jul!AJ23 -> 0 | F28: =Ags!AJ23 -> 0 | G28: =Sep!AJ23 -> 0 | H28: =Okt!AJ23 -> 0 | I28: =Nov!AJ23 -> 0 | J28: =Des!AJ23 -> 0 | K28: =SUM(E28:J28) -> 0 | M28: =Jan!AJ23 -> 0 | N28: =Feb!AJ23 -> 0 | O28: =Mar!AJ23 -> 0 | P28: =Apr!AJ23 -> 0 | Q28: =Mei!AJ23 -> 0 | R28: =Jun!AJ23 -> 0 | S28: =SUM(M28:R28) -> 0 | T28: =K28+S28 -> 0
A29: 10 | B29: =IF(INDIRECT("'Data Murid'!B" & ROW(A17))="", "", INDIRECT("'Data Murid'!B" & ROW(A17))) -> #REF! | C29: =IF(INDIRECT("'Data Murid'!C" & ROW(B17))="", "", INDIRECT("'Data Murid'!C" & ROW(B17))) -> #REF! | D29: =IF(INDIRECT("'Data Murid'!D" & ROW(C17))="", "", LEFT(INDIRECT("'Data Murid'!D" & ROW(C17)),1)) -> #REF! | E29: =Jul!AJ24 -> 0 | F29: =Ags!AJ24 -> 0 | G29: =Sep!AJ24 -> 0 | H29: =Okt!AJ24 -> 0 | I29: =Nov!AJ24 -> 0 | J29: =Des!AJ24 -> 0 | K29: =SUM(E29:J29) -> 0 | M29: =Jan!AJ24 -> 0 | N29: =Feb!AJ24 -> 0 | O29: =Mar!AJ24 -> 0 | P29: =Apr!AJ24 -> 0 | Q29: =Mei!AJ24 -> 0 | R29: =Jun!AJ24 -> 0 | S29: =SUM(M29:R29) -> 0 | T29: =K29+S29 -> 0
A30: 11 | B30: =IF(INDIRECT("'Data Murid'!B" & ROW(A18))="", "", INDIRECT("'Data Murid'!B" & ROW(A18))) -> #REF! | C30: =IF(INDIRECT("'Data Murid'!C" & ROW(B18))="", "", INDIRECT("'Data Murid'!C" & ROW(B18))) -> #REF! | D30: =IF(INDIRECT("'Data Murid'!D" & ROW(C18))="", "", LEFT(INDIRECT("'Data Murid'!D" & ROW(C18)),1)) -> #REF! | E30: =Jul!AJ25 -> 0 | F30: =Ags!AJ25 -> 0 | G30: =Sep!AJ25 -> 0 | H30: =Okt!AJ25 -> 0 | I30: =Nov!AJ25 -> 0 | J30: =Des!AJ25 -> 0 | K30: =SUM(E30:J30) -> 0 | M30: =Jan!AJ25 -> 0 | N30: =Feb!AJ25 -> 0 | O30: =Mar!AJ25 -> 0 | P30: =Apr!AJ25 -> 0 | Q30: =Mei!AJ25 -> 0 | R30: =Jun!AJ25 -> 0 | S30: =SUM(M30:R30) -> 0 | T30: =K30+S30 -> 0
A31: 12 | B31: =IF(INDIRECT("'Data Murid'!B" & ROW(A19))="", "", INDIRECT("'Data Murid'!B" & ROW(A19))) -> #REF! | C31: =IF(INDIRECT("'Data Murid'!C" & ROW(B19))="", "", INDIRECT("'Data Murid'!C" & ROW(B19))) -> #REF! | D31: =IF(INDIRECT("'Data Murid'!D" & ROW(C19))="", "", LEFT(INDIRECT("'Data Murid'!D" & ROW(C19)),1)) -> #REF! | E31: =Jul!AJ26 -> 0 | F31: =Ags!AJ26 -> 0 | G31: =Sep!AJ26 -> 0 | H31: =Okt!AJ26 -> 0 | I31: =Nov!AJ26 -> 0 | J31: =Des!AJ26 -> 0 | K31: =SUM(E31:J31) -> 0 | M31: =Jan!AJ26 -> 0 | N31: =Feb!AJ26 -> 0 | O31: =Mar!AJ26 -> 0 | P31: =Apr!AJ26 -> 0 | Q31: =Mei!AJ26 -> 0 | R31: =Jun!AJ26 -> 0 | S31: =SUM(M31:R31) -> 0 | T31: =K31+S31 -> 0
... A59: 40 | B59: =IF(INDIRECT("'Data Murid'!B" & ROW(A47))="", "", INDIRECT("'Data Murid'!B" & ROW(A47))) -> #REF! | C59: =IF(INDIRECT("'Data Murid'!C" & ROW(B47))="", "", INDIRECT("'Data Murid'!C" & ROW(B47))) -> #REF! | D59: =IF(INDIRECT("'Data Murid'!D" & ROW(C47))="", "", LEFT(INDIRECT("'Data Murid'!D" & ROW(C47)),1)) -> #REF! | E59: =Jul!AJ54 -> 0 | F59: =Ags!AJ54 -> 0 | G59: =Sep!AJ54 -> 0 | H59: =Okt!AJ54 -> 0 | I59: =Nov!AJ54 -> 0 | J59: =Des!AJ54 -> 0 | K59: =SUM(E59:J59) -> 0 | M59: =Jan!AJ54 -> 0 | N59: =Feb!AJ54 -> 0 | O59: =Mar!AJ54 -> 0 | P59: =Apr!AJ54 -> 0 | Q59: =Mei!AJ54 -> 0 | R59: =Jun!AJ54 -> 0 | S59: =SUM(M59:R59) -> 0 | T59: =K59+S59 -> 0

Sheet Jul
A1: PEMERINTAH PROVINSI JAWA TIMUR
A2: DINAS PENDIDIKAN
A3: SEKOLAH MENENGAH ATAS NEGERI 21 SURABAYA
A4: Jl. Argopuro 11-15 Surabaya Telp. 031-5350753 Fax. 031-5341530
A6: DAFTAR KETERLAMBATAN SISWA
A7: ='rekap absensi seluruhnya'!E7 -> #REF!
A9: NO | C9: NAMA LENGKAP | D9: JK | E9: PERTEMUAN TGL (ABSENSI) | AJ9: Total Keterlambatan
A11: Urut | B11: NIS | E11: =DATE(--LEFT(INDIRECT("'Data Murid'!A3"),4),7,1) -> #REF! | F11: =IF(MONTH(E11+1)=MONTH($E11), E11+1, "") -> #REF! | G11: =IF(MONTH(F11+1)=MONTH($E11), F11+1, "") -> #REF! | H11: =IF(MONTH(G11+1)=MONTH($E11), G11+1, "") -> #REF! | I11: =IF(MONTH(H11+1)=MONTH($E11), H11+1, "") -> #REF! | J11: =IF(MONTH(I11+1)=MONTH($E11), I11+1, "") -> #REF! | K11: =IF(MONTH(J11+1)=MONTH($E11), J11+1, "") -> #REF! | L11: =IF(MONTH(K11+1)=MONTH($E11), K11+1, "") -> #REF! | M11: =IF(MONTH(L11+1)=MONTH($E11), L11+1, "") -> #REF! | ... AI11: =IF(MONTH(AH11+1)=MONTH($E11), AH11+1, "") -> #REF!
E12: =IF(E11="","",TEXT(E11,"[$-id]ddd")) -> #REF! | F12: =IF(F11="","",TEXT(F11,"[$-id]ddd")) -> #REF! | G12: =IF(G11="","",TEXT(G11,"[$-id]ddd")) -> #REF! | H12: =IF(H11="","",TEXT(H11,"[$-id]ddd")) -> #REF! | I12: =IF(I11="","",TEXT(I11,"[$-id]ddd")) -> #REF! | J12: =IF(J11="","",TEXT(J11,"[$-id]ddd")) -> #REF! | K12: =IF(K11="","",TEXT(K11,"[$-id]ddd")) -> #REF! | L12: =IF(L11="","",TEXT(L11,"[$-id]ddd")) -> #REF! | ... AI12: =IF(AI11="","",TEXT(AI11,"[$-id]ddd")) -> #REF!
A14: ='rekap absensi seluruhnya'!A19:T19 -> #REF!
A15: 1 | B15: ='rekap absensi seluruhnya'!B20 -> #REF! | C15: ='rekap absensi seluruhnya'!C20 -> #REF! | D15: ='rekap absensi seluruhnya'!D20 -> #REF! | E15: {=IF(OR(E$11="", INDIRECT("'Data Murid'!$E" & ROW($E8))=""), "", IF(ISNUMBER(SEARCH(TEXT(E$11,"mm/dd/yyyy"), INDIRECT("'Data Murid'!$E" & ROW($E8)))), "✔", ""))} -> #REF! | F15: {=IF(OR(F$11="", INDIRECT("'Data Murid'!$E" & ROW($E8))=""), "", IF(ISNUMBER(SEARCH(TEXT(F$11,"mm/dd/yyyy"), INDIRECT("'Data Murid'!$E" & ROW($E8)))), "✔", ""))} -> #REF! | G15: {=IF(OR(G$11="", INDIRECT("'Data Murid'!$E" & ROW($E8))=""), "", IF(ISNUMBER(SEARCH(TEXT(G$11,"mm/dd/yyyy"), INDIRECT("'Data Murid'!$E" & ROW($E8)))), "✔", ""))} -> #REF! | H15: {=IF(OR(H$11="", INDIRECT("'Data Murid'!$E" & ROW($E8))=""), "", IF(ISNUMBER(SEARCH(TEXT(H$11,"mm/dd/yyyy"), INDIRECT("'Data Murid'!$E" & ROW($E8)))), "✔", ""))} -> #REF! | I15: {=IF(OR(I$11="", INDIRECT("'Data Murid'!$E" & ROW($E8))=""), "", IF(ISNUMBER(SEARCH(TEXT(I$11,"mm/dd/yyyy"), INDIRECT("'Data Murid'!$E" & ROW($E8)))), "✔", ""))} -> #REF! | J15: {=IF(OR(J$11="", INDIRECT("'Data Murid'!$E" & ROW($E8))=""), "", IF(ISNUMBER(SEARCH(TEXT(J$11,"mm/dd/yyyy"), INDIRECT("'Data Murid'!$E" & ROW($E8)))), "✔", ""))} -> #REF! | K15: {=IF(OR(K$11="", INDIRECT("'Data Murid'!$E" & ROW($E8))=""), "", IF(ISNUMBER(SEARCH(TEXT(K$11,"mm/dd/yyyy"), INDIRECT("'Data Murid'!$E" & ROW($E8)))), "✔", ""))} -> #REF! | L15: {=IF(OR(L$11="", INDIRECT("'Data Murid'!$E" & ROW($E8))=""), "", IF(ISNUMBER(SEARCH(TEXT(L$11,"mm/dd/yyyy"), INDIRECT("'Data Murid'!$E" & ROW($E8)))), "✔", ""))} -> #REF! | ... AI15: {=IF(OR(AI$11="", INDIRECT("'Data Murid'!$E" & ROW($E8))=""), "", IF(ISNUMBER(SEARCH(TEXT(AI$11,"mm/dd/yyyy"), INDIRECT("'Data Murid'!$E" & ROW($E8)))), "✔", ""))} -> #REF! | AJ15: =COUNTIF(E15:AI15, "✔") -> 0
A16: 2 | B16: ='rekap absensi seluruhnya'!B21 -> #REF! | C16: ='rekap absensi seluruhnya'!C21 -> #REF! | D16: ='rekap absensi seluruhnya'!D21 -> #REF! | E16: {=IF(OR(E$11="", INDIRECT("'Data Murid'!$E" & ROW($E9))=""), "", IF(ISNUMBER(SEARCH(TEXT(E$11,"mm/dd/yyyy"), INDIRECT("'Data Murid'!$E" & ROW($E9)))), "✔", ""))} -> #REF! | F16: {=IF(OR(F$11="", INDIRECT("'Data Murid'!$E" & ROW($E9))=""), "", IF(ISNUMBER(SEARCH(TEXT(F$11,"mm/dd/yyyy"), INDIRECT("'Data Murid'!$E" & ROW($E9)))), "✔", ""))} -> #REF! | G16: {=IF(OR(G$11="", INDIRECT("'Data Murid'!$E" & ROW($E9))=""), "", IF(ISNUMBER(SEARCH(TEXT(G$11,"mm/dd/yyyy"), INDIRECT("'Data Murid'!$E" & ROW($E9)))), "✔", ""))} -> #REF! | H16: {=IF(OR(H$11="", INDIRECT("'Data Murid'!$E" & ROW($E9))=""), "", IF(ISNUMBER(SEARCH(TEXT(H$11,"mm/dd/yyyy"), INDIRECT("'Data Murid'!$E" & ROW($E9)))), "✔", ""))} -> #REF! | I16: {=IF(OR(I$11="", INDIRECT("'Data Murid'!$E" & ROW($E9))=""), "", IF(ISNUMBER(SEARCH(TEXT(I$11,"mm/dd/yyyy"), INDIRECT("'Data Murid'!$E" & ROW($E9)))), "✔", ""))} -> #REF! | J16: {=IF(OR(J$11="", INDIRECT("'Data Murid'!$E" & ROW($E9))=""), "", IF(ISNUMBER(SEARCH(TEXT(J$11,"mm/dd/yyyy"), INDIRECT("'Data Murid'!$E" & ROW($E9)))), "✔", ""))} -> #REF! | K16: {=IF(OR(K$11="", INDIRECT("'Data Murid'!$E" & ROW($E9))=""), "", IF(ISNUMBER(SEARCH(TEXT(K$11,"mm/dd/yyyy"), INDIRECT("'Data Murid'!$E" & ROW($E9)))), "✔", ""))} -> #REF! | L16: {=IF(OR(L$11="", INDIRECT("'Data Murid'!$E" & ROW($E9))=""), "", IF(ISNUMBER(SEARCH(TEXT(L$11,"mm/dd/yyyy"), INDIRECT("'Data Murid'!$E" & ROW($E9)))), "✔", ""))} -> #REF! | ... AI16: {=IF(OR(AI$11="", INDIRECT("'Data Murid'!$E" & ROW($E9))=""), "", IF(ISNUMBER(SEARCH(TEXT(AI$11,"mm/dd/yyyy"), INDIRECT("'Data Murid'!$E" & ROW($E9)))), "✔", ""))} -> #REF! | AJ16: =COUNTIF(E16:AI16, "✔") -> 0
A17: 3 | B17: ='rekap absensi seluruhnya'!B22 -> #REF! | C17: ='rekap absensi seluruhnya'!C22 -> #REF! | D17: ='rekap absensi seluruhnya'!D22 -> #REF! | E17: {=IF(OR(E$11="", INDIRECT("'Data Murid'!$E" & ROW($E10))=""), "", IF(ISNUMBER(SEARCH(TEXT(E$11,"mm/dd/yyyy"), INDIRECT("'Data Murid'!$E" & ROW($E10)))), "✔", ""))} -> #REF! | F17: {=IF(OR(F$11="", INDIRECT("'Data Murid'!$E" & ROW($E10))=""), "", IF(ISNUMBER(SEARCH(TEXT(F$11,"mm/dd/yyyy"), INDIRECT("'Data Murid'!$E" & ROW($E10)))), "✔", ""))} -> #REF! | G17: {=IF(OR(G$11="", INDIRECT("'Data Murid'!$E" & ROW($E10))=""), "", IF(ISNUMBER(SEARCH(TEXT(G$11,"mm/dd/yyyy"), INDIRECT("'Data Murid'!$E" & ROW($E10)))), "✔", ""))} -> #REF! | H17: {=IF(OR(H$11="", INDIRECT("'Data Murid'!$E" & ROW($E10))=""), "", IF(ISNUMBER(SEARCH(TEXT(H$11,"mm/dd/yyyy"), INDIRECT("'Data Murid'!$E" & ROW($E10)))), "✔", ""))} -> #REF! | I17: {=IF(OR(I$11="", INDIRECT("'Data Murid'!$E" & ROW($E10))=""), "", IF(ISNUMBER(SEARCH(TEXT(I$11,"mm/dd/yyyy"), INDIRECT("'Data Murid'!$E" & ROW($E10)))), "✔", ""))} -> #REF! | J17: {=IF(OR(J$11="", INDIRECT("'Data Murid'!$E" & ROW($E10))=""), "", IF(ISNUMBER(SEARCH(TEXT(J$11,"mm/dd/yyyy"), INDIRECT("'Data Murid'!$E" & ROW($E10)))), "✔", ""))} -> #REF! | K17: {=IF(OR(K$11="", INDIRECT("'Data Murid'!$E" & ROW($E10))=""), "", IF(ISNUMBER(SEARCH(TEXT(K$11,"mm/dd/yyyy"), INDIRECT("'Data Murid'!$E" & ROW($E10)))), "✔", ""))} -> #REF! | L17: {=IF(OR(L$11="", INDIRECT("'Data Murid'!$E" & ROW($E10))=""), "", IF(ISNUMBER(SEARCH(TEXT(L$11,"mm/dd/yyyy"), INDIRECT("'Data Murid'!$E" & ROW($E10)))), "✔", ""))} -> #REF! | ... AI17: {=IF(OR(AI$11="", INDIRECT("'Data Murid'!$E" & ROW($E10))=""), "", IF(ISNUMBER(SEARCH(TEXT(AI$11,"mm/dd/yyyy"), INDIRECT("'Data Murid'!$E" & ROW($E10)))), "✔", ""))} -> #REF! | AJ17: =COUNTIF(E17:AI17, "✔") -> 0
A18: 4 | B18: ='rekap absensi seluruhnya'!B23 -> #REF! | C18: ='rekap absensi seluruhnya'!C23 -> #REF! | D18: ='rekap absensi seluruhnya'!D23 -> #REF! | E18: {=IF(OR(E$11="", INDIRECT("'Data Murid'!$E" & ROW($E11))=""), "", IF(ISNUMBER(SEARCH(TEXT(E$11,"mm/dd/yyyy"), INDIRECT("'Data Murid'!$E" & ROW($E11)))), "✔", ""))} -> #REF! | F18: {=IF(OR(F$11="", INDIRECT("'Data Murid'!$E" & ROW($E11))=""), "", IF(ISNUMBER(SEARCH(TEXT(F$11,"mm/dd/yyyy"), INDIRECT("'Data Murid'!$E" & ROW($E11)))), "✔", ""))} -> #REF! | G18: {=IF(OR(G$11="", INDIRECT("'Data Murid'!$E" & ROW($E11))=""), "", IF(ISNUMBER(SEARCH(TEXT(G$11,"mm/dd/yyyy"), INDIRECT("'Data Murid'!$E" & ROW($E11)))), "✔", ""))} -> #REF! | H18: {=IF(OR(H$11="", INDIRECT("'Data Murid'!$E" & ROW($E11))=""), "", IF(ISNUMBER(SEARCH(TEXT(H$11,"mm/dd/yyyy"), INDIRECT("'Data Murid'!$E" & ROW($E11)))), "✔", ""))} -> #REF! | I18: {=IF(OR(I$11="", INDIRECT("'Data Murid'!$E" & ROW($E11))=""), "", IF(ISNUMBER(SEARCH(TEXT(I$11,"mm/dd/yyyy"), INDIRECT("'Data Murid'!$E" & ROW($E11)))), "✔", ""))} -> #REF! | J18: {=IF(OR(J$11="", INDIRECT("'Data Murid'!$E" & ROW($E11))=""), "", IF(ISNUMBER(SEARCH(TEXT(J$11,"mm/dd/yyyy"), INDIRECT("'Data Murid'!$E" & ROW($E11)))), "✔", ""))} -> #REF! | K18: {=IF(OR(K$11="", INDIRECT("'Data Murid'!$E" & ROW($E11))=""), "", IF(ISNUMBER(SEARCH(TEXT(K$11,"mm/dd/yyyy"), INDIRECT("'Data Murid'!$E" & ROW($E11)))), "✔", ""))} -> #REF! | L18: {=IF(OR(L$11="", INDIRECT("'Data Murid'!$E" & ROW($E11))=""), "", IF(ISNUMBER(SEARCH(TEXT(L$11,"mm/dd/yyyy"), INDIRECT("'Data Murid'!$E" & ROW($E11)))), "✔", ""))} -> #REF! | ... AI18: {=IF(OR(AI$11="", INDIRECT("'Data Murid'!$E" & ROW($E11))=""), "", IF(ISNUMBER(SEARCH(TEXT(AI$11,"mm/dd/yyyy"), INDIRECT("'Data Murid'!$E" & ROW($E11)))), "✔", ""))} -> #REF! | AJ18: =COUNTIF(E18:AI18, "✔") -> 0
A19: 5 | B19: ='rekap absensi seluruhnya'!B24 -> #REF! | C19: ='rekap absensi seluruhnya'!C24 -> #REF! | D19: ='rekap absensi seluruhnya'!D24 -> #REF! | E19: {=IF(OR(E$11="", INDIRECT("'Data Murid'!$E" & ROW($E12))=""), "", IF(ISNUMBER(SEARCH(TEXT(E$11,"mm/dd/yyyy"), INDIRECT("'Data Murid'!$E" & ROW($E12)))), "✔", ""))} -> #REF! | F19: {=IF(OR(F$11="", INDIRECT("'Data Murid'!$E" & ROW($E12))=""), "", IF(ISNUMBER(SEARCH(TEXT(F$11,"mm/dd/yyyy"), INDIRECT("'Data Murid'!$E" & ROW($E12)))), "✔", ""))} -> #REF! | G19: {=IF(OR(G$11="", INDIRECT("'Data Murid'!$E" & ROW($E12))=""), "", IF(ISNUMBER(SEARCH(TEXT(G$11,"mm/dd/yyyy"), INDIRECT("'Data Murid'!$E" & ROW($E12)))), "✔", ""))} -> #REF! | H19: {=IF(OR(H$11="", INDIRECT("'Data Murid'!$E" & ROW($E12))=""), "", IF(ISNUMBER(SEARCH(TEXT(H$11,"mm/dd/yyyy"), INDIRECT("'Data Murid'!$E" & ROW($E12)))), "✔", ""))} -> #REF! | I19: {=IF(OR(I$11="", INDIRECT("'Data Murid'!$E" & ROW($E12))=""), "", IF(ISNUMBER(SEARCH(TEXT(I$11,"mm/dd/yyyy"), INDIRECT("'Data Murid'!$E" & ROW($E12)))), "✔", ""))} -> #REF! | J19: {=IF(OR(J$11="", INDIRECT("'Data Murid'!$E" & ROW($E12))=""), "", IF(ISNUMBER(SEARCH(TEXT(J$11,"mm/dd/yyyy"), INDIRECT("'Data Murid'!$E" & ROW($E12)))), "✔", ""))} -> #REF! | K19: {=IF(OR(K$11="", INDIRECT("'Data Murid'!$E" & ROW($E12))=""), "", IF(ISNUMBER(SEARCH(TEXT(K$11,"mm/dd/yyyy"), INDIRECT("'Data Murid'!$E" & ROW($E12)))), "✔", ""))} -> #REF! | L19: {=IF(OR(L$11="", INDIRECT("'Data Murid'!$E" & ROW($E12))=""), "", IF(ISNUMBER(SEARCH(TEXT(L$11,"mm/dd/yyyy"), INDIRECT("'Data Murid'!$E" & ROW($E12)))), "✔", ""))} -> #REF! | ... AI19: {=IF(OR(AI$11="", INDIRECT("'Data Murid'!$E" & ROW($E12))=""), "", IF(ISNUMBER(SEARCH(TEXT(AI$11,"mm/dd/yyyy"), INDIRECT("'Data Murid'!$E" & ROW($E12)))), "✔", ""))} -> #REF! | AJ19: =COUNTIF(E19:AI19, "✔") -> 0
A20: 6 | B20: ='rekap absensi seluruhnya'!B25 -> #REF! | C20: ='rekap absensi seluruhnya'!C25 -> #REF! | D20: ='rekap absensi seluruhnya'!D25 -> #REF! | E20: {=IF(OR(E$11="", INDIRECT("'Data Murid'!$E" & ROW($E13))=""), "", IF(ISNUMBER(SEARCH(TEXT(E$11,"mm/dd/yyyy"), INDIRECT("'Data Murid'!$E" & ROW($E13)))), "✔", ""))} -> #REF! | F20: {=IF(OR(F$11="", INDIRECT("'Data Murid'!$E" & ROW($E13))=""), "", IF(ISNUMBER(SEARCH(TEXT(F$11,"mm/dd/yyyy"), INDIRECT("'Data Murid'!$E" & ROW($E13)))), "✔", ""))} -> #REF! | G20: {=IF(OR(G$11="", INDIRECT("'Data Murid'!$E" & ROW($E13))=""), "", IF(ISNUMBER(SEARCH(TEXT(G$11,"mm/dd/yyyy"), INDIRECT("'Data Murid'!$E" & ROW($E13)))), "✔", ""))} -> #REF! | H20: {=IF(OR(H$11="", INDIRECT("'Data Murid'!$E" & ROW($E13))=""), "", IF(ISNUMBER(SEARCH(TEXT(H$11,"mm/dd/yyyy"), INDIRECT("'Data Murid'!$E" & ROW($E13)))), "✔", ""))} -> #REF! | I20: {=IF(OR(I$11="", INDIRECT("'Data Murid'!$E" & ROW($E13))=""), "", IF(ISNUMBER(SEARCH(TEXT(I$11,"mm/dd/yyyy"), INDIRECT("'Data Murid'!$E" & ROW($E13)))), "✔", ""))} -> #REF! | J20: {=IF(OR(J$11="", INDIRECT("'Data Murid'!$E" & ROW($E13))=""), "", IF(ISNUMBER(SEARCH(TEXT(J$11,"mm/dd/yyyy"), INDIRECT("'Data Murid'!$E" & ROW($E13)))), "✔", ""))} -> #REF! | K20: {=IF(OR(K$11="", INDIRECT("'Data Murid'!$E" & ROW($E13))=""), "", IF(ISNUMBER(SEARCH(TEXT(K$11,"mm/dd/yyyy"), INDIRECT("'Data Murid'!$E" & ROW($E13)))), "✔", ""))} -> #REF! | L20: {=IF(OR(L$11="", INDIRECT("'Data Murid'!$E" & ROW($E13))=""), "", IF(ISNUMBER(SEARCH(TEXT(L$11,"mm/dd/yyyy"), INDIRECT("'Data Murid'!$E" & ROW($E13)))), "✔", ""))} -> #REF! | ... AI20: {=IF(OR(AI$11="", INDIRECT("'Data Murid'!$E" & ROW($E13))=""), "", IF(ISNUMBER(SEARCH(TEXT(AI$11,"mm/dd/yyyy"), INDIRECT("'Data Murid'!$E" & ROW($E13)))), "✔", ""))} -> #REF! | AJ20: =COUNTIF(E20:AI20, "✔") -> 0
A21: 7 | B21: ='rekap absensi seluruhnya'!B26 -> #REF! | C21: ='rekap absensi seluruhnya'!C26 -> #REF! | D21: ='rekap absensi seluruhnya'!D26 -> #REF! | E21: {=IF(OR(E$11="", INDIRECT("'Data Murid'!$E" & ROW($E14))=""), "", IF(ISNUMBER(SEARCH(TEXT(E$11,"mm/dd/yyyy"), INDIRECT("'Data Murid'!$E" & ROW($E14)))), "✔", ""))} -> #REF! | F21: {=IF(OR(F$11="", INDIRECT("'Data Murid'!$E" & ROW($E14))=""), "", IF(ISNUMBER(SEARCH(TEXT(F$11,"mm/dd/yyyy"), INDIRECT("'Data Murid'!$E" & ROW($E14)))), "✔", ""))} -> #REF! | G21: {=IF(OR(G$11="", INDIRECT("'Data Murid'!$E" & ROW($E14))=""), "", IF(ISNUMBER(SEARCH(TEXT(G$11,"mm/dd/yyyy"), INDIRECT("'Data Murid'!$E" & ROW($E14)))), "✔", ""))} -> #REF! | H21: {=IF(OR(H$11="", INDIRECT("'Data Murid'!$E" & ROW($E14))=""), "", IF(ISNUMBER(SEARCH(TEXT(H$11,"mm/dd/yyyy"), INDIRECT("'Data Murid'!$E" & ROW($E14)))), "✔", ""))} -> #REF! | I21: {=IF(OR(I$11="", INDIRECT("'Data Murid'!$E" & ROW($E14))=""), "", IF(ISNUMBER(SEARCH(TEXT(I$11,"mm/dd/yyyy"), INDIRECT("'Data Murid'!$E" & ROW($E14)))), "✔", ""))} -> #REF! | J21: {=IF(OR(J$11="", INDIRECT("'Data Murid'!$E" & ROW($E14))=""), "", IF(ISNUMBER(SEARCH(TEXT(J$11,"mm/dd/yyyy"), INDIRECT("'Data Murid'!$E" & ROW($E14)))), "✔", ""))} -> #REF! | K21: {=IF(OR(K$11="", INDIRECT("'Data Murid'!$E" & ROW($E14))=""), "", IF(ISNUMBER(SEARCH(TEXT(K$11,"mm/dd/yyyy"), INDIRECT("'Data Murid'!$E" & ROW($E14)))), "✔", ""))} -> #REF! | L21: {=IF(OR(L$11="", INDIRECT("'Data Murid'!$E" & ROW($E14))=""), "", IF(ISNUMBER(SEARCH(TEXT(L$11,"mm/dd/yyyy"), INDIRECT("'Data Murid'!$E" & ROW($E14)))), "✔", ""))} -> #REF! | ... AI21: {=IF(OR(AI$11="", INDIRECT("'Data Murid'!$E" & ROW($E14))=""), "", IF(ISNUMBER(SEARCH(TEXT(AI$11,"mm/dd/yyyy"), INDIRECT("'Data Murid'!$E" & ROW($E14)))), "✔", ""))} -> #REF! | AJ21: =COUNTIF(E21:AI21, "✔") -> 0
A22: 8 | B22: ='rekap absensi seluruhnya'!B27 -> #REF! | C22: ='rekap absensi seluruhnya'!C27 -> #REF! | D22: ='rekap absensi seluruhnya'!D27 -> #REF! | E22: {=IF(OR(E$11="", INDIRECT("'Data Murid'!$E" & ROW($E15))=""), "", IF(ISNUMBER(SEARCH(TEXT(E$11,"mm/dd/yyyy"), INDIRECT("'Data Murid'!$E" & ROW($E15)))), "✔", ""))} -> #REF! | F22: {=IF(OR(F$11="", INDIRECT("'Data Murid'!$E" & ROW($E15))=""), "", IF(ISNUMBER(SEARCH(TEXT(F$11,"mm/dd/yyyy"), INDIRECT("'Data Murid'!$E" & ROW($E15)))), "✔", ""))} -> #REF! | G22: {=IF(OR(G$11="", INDIRECT("'Data Murid'!$E" & ROW($E15))=""), "", IF(ISNUMBER(SEARCH(TEXT(G$11,"mm/dd/yyyy"), INDIRECT("'Data Murid'!$E" & ROW($E15)))), "✔", ""))} -> #REF! | H22: {=IF(OR(H$11="", INDIRECT("'Data Murid'!$E" & ROW($E15))=""), "", IF(ISNUMBER(SEARCH(TEXT(H$11,"mm/dd/yyyy"), INDIRECT("'Data Murid'!$E" & ROW($E15)))), "✔", ""))} -> #REF! | I22: {=IF(OR(I$11="", INDIRECT("'Data Murid'!$E" & ROW($E15))=""), "", IF(ISNUMBER(SEARCH(TEXT(I$11,"mm/dd/yyyy"), INDIRECT("'Data Murid'!$E" & ROW($E15)))), "✔", ""))} -> #REF! | J22: {=IF(OR(J$11="", INDIRECT("'Data Murid'!$E" & ROW($E15))=""), "", IF(ISNUMBER(SEARCH(TEXT(J$11,"mm/dd/yyyy"), INDIRECT("'Data Murid'!$E" & ROW($E15)))), "✔", ""))} -> #REF! | K22: {=IF(OR(K$11="", INDIRECT("'Data Murid'!$E" & ROW($E15))=""), "", IF(ISNUMBER(SEARCH(TEXT(K$11,"mm/dd/yyyy"), INDIRECT("'Data Murid'!$E" & ROW($E15)))), "✔", ""))} -> #REF! | L22: {=IF(OR(L$11="", INDIRECT("'Data Murid'!$E" & ROW($E15))=""), "", IF(ISNUMBER(SEARCH(TEXT(L$11,"mm/dd/yyyy"), INDIRECT("'Data Murid'!$E" & ROW($E15)))), "✔", ""))} -> #REF! | ... AI22: {=IF(OR(AI$11="", INDIRECT("'Data Murid'!$E" & ROW($E15))=""), "", IF(ISNUMBER(SEARCH(TEXT(AI$11,"mm/dd/yyyy"), INDIRECT("'Data Murid'!$E" & ROW($E15)))), "✔", ""))} -> #REF! | AJ22: =COUNTIF(E22:AI22, "✔") -> 0
A23: 9 | B23: ='rekap absensi seluruhnya'!B28 -> #REF! | C23: ='rekap absensi seluruhnya'!C28 -> #REF! | D23: ='rekap absensi seluruhnya'!D28 -> #REF! | E23: {=IF(OR(E$11="", INDIRECT("'Data Murid'!$E" & ROW($E16))=""), "", IF(ISNUMBER(SEARCH(TEXT(E$11,"mm/dd/yyyy"), INDIRECT("'Data Murid'!$E" & ROW($E16)))), "✔", ""))} -> #REF! | F23: {=IF(OR(F$11="", INDIRECT("'Data Murid'!$E" & ROW($E16))=""), "", IF(ISNUMBER(SEARCH(TEXT(F$11,"mm/dd/yyyy"), INDIRECT("'Data Murid'!$E" & ROW($E16)))), "✔", ""))} -> #REF! | G23: {=IF(OR(G$11="", INDIRECT("'Data Murid'!$E" & ROW($E16))=""), "", IF(ISNUMBER(SEARCH(TEXT(G$11,"mm/dd/yyyy"), INDIRECT("'Data Murid'!$E" & ROW($E16)))), "✔", ""))} -> #REF! | H23: {=IF(OR(H$11="", INDIRECT("'Data Murid'!$E" & ROW($E16))=""), "", IF(ISNUMBER(SEARCH(TEXT(H$11,"mm/dd/yyyy"), INDIRECT("'Data Murid'!$E" & ROW($E16)))), "✔", ""))} -> #REF! | I23: {=IF(OR(I$11="", INDIRECT("'Data Murid'!$E" & ROW($E16))=""), "", IF(ISNUMBER(SEARCH(TEXT(I$11,"mm/dd/yyyy"), INDIRECT("'Data Murid'!$E" & ROW($E16)))), "✔", ""))} -> #REF! | J23: {=IF(OR(J$11="", INDIRECT("'Data Murid'!$E" & ROW($E16))=""), "", IF(ISNUMBER(SEARCH(TEXT(J$11,"mm/dd/yyyy"), INDIRECT("'Data Murid'!$E" & ROW($E16)))), "✔", ""))} -> #REF! | K23: {=IF(OR(K$11="", INDIRECT("'Data Murid'!$E" & ROW($E16))=""), "", IF(ISNUMBER(SEARCH(TEXT(K$11,"mm/dd/yyyy"), INDIRECT("'Data Murid'!$E" & ROW($E16)))), "✔", ""))} -> #REF! | L23: {=IF(OR(L$11="", INDIRECT("'Data Murid'!$E" & ROW($E16))=""), "", IF(ISNUMBER(SEARCH(TEXT(L$11,"mm/dd/yyyy"), INDIRECT("'Data Murid'!$E" & ROW($E16)))), "✔", ""))} -> #REF! | ... AI23: {=IF(OR(AI$11="", INDIRECT("'Data Murid'!$E" & ROW($E16))=""), "", IF(ISNUMBER(SEARCH(TEXT(AI$11,"mm/dd/yyyy"), INDIRECT("'Data Murid'!$E" & ROW($E16)))), "✔", ""))} -> #REF! | AJ23: =COUNTIF(E23:AI23, "✔") -> 0
A24: 10 | B24: ='rekap absensi seluruhnya'!B29 -> #REF! | C24: ='rekap absensi seluruhnya'!C29 -> #REF! | D24: ='rekap absensi seluruhnya'!D29 -> #REF! | E24: {=IF(OR(E$11="", INDIRECT("'Data Murid'!$E" & ROW($E17))=""), "", IF(ISNUMBER(SEARCH(TEXT(E$11,"mm/dd/yyyy"), INDIRECT("'Data Murid'!$E" & ROW($E17)))), "✔", ""))} -> #REF! | F24: {=IF(OR(F$11="", INDIRECT("'Data Murid'!$E" & ROW($E17))=""), "", IF(ISNUMBER(SEARCH(TEXT(F$11,"mm/dd/yyyy"), INDIRECT("'Data Murid'!$E" & ROW($E17)))), "✔", ""))} -> #REF! | G24: {=IF(OR(G$11="", INDIRECT("'Data Murid'!$E" & ROW($E17))=""), "", IF(ISNUMBER(SEARCH(TEXT(G$11,"mm/dd/yyyy"), INDIRECT("'Data Murid'!$E" & ROW($E17)))), "✔", ""))} -> #REF! | H24: {=IF(OR(H$11="", INDIRECT("'Data Murid'!$E" & ROW($E17))=""), "", IF(ISNUMBER(SEARCH(TEXT(H$11,"mm/dd/yyyy"), INDIRECT("'Data Murid'!$E" & ROW($E17)))), "✔", ""))} -> #REF! | I24: {=IF(OR(I$11="", INDIRECT("'Data Murid'!$E" & ROW($E17))=""), "", IF(ISNUMBER(SEARCH(TEXT(I$11,"mm/dd/yyyy"), INDIRECT("'Data Murid'!$E" & ROW($E17)))), "✔", ""))} -> #REF! | J24: {=IF(OR(J$11="", INDIRECT("'Data Murid'!$E" & ROW($E17))=""), "", IF(ISNUMBER(SEARCH(TEXT(J$11,"mm/dd/yyyy"), INDIRECT("'Data Murid'!$E" & ROW($E17)))), "✔", ""))} -> #REF! | K24: {=IF(OR(K$11="", INDIRECT("'Data Murid'!$E" & ROW($E17))=""), "", IF(ISNUMBER(SEARCH(TEXT(K$11,"mm/dd/yyyy"), INDIRECT("'Data Murid'!$E" & ROW($E17)))), "✔", ""))} -> #REF! | L24: {=IF(OR(L$11="", INDIRECT("'Data Murid'!$E" & ROW($E17))=""), "", IF(ISNUMBER(SEARCH(TEXT(L$11,"mm/dd/yyyy"), INDIRECT("'Data Murid'!$E" & ROW($E17)))), "✔", ""))} -> #REF! | ... AI24: {=IF(OR(AI$11="", INDIRECT("'Data Murid'!$E" & ROW($E17))=""), "", IF(ISNUMBER(SEARCH(TEXT(AI$11,"mm/dd/yyyy"), INDIRECT("'Data Murid'!$E" & ROW($E17)))), "✔", ""))} -> #REF! | AJ24: =COUNTIF(E24:AI24, "✔") -> 0
A25: 11 | B25: ='rekap absensi seluruhnya'!B30 -> #REF! | C25: ='rekap absensi seluruhnya'!C30 -> #REF! | D25: ='rekap absensi seluruhnya'!D30 -> #REF! | E25: {=IF(OR(E$11="", INDIRECT("'Data Murid'!$E" & ROW($E18))=""), "", IF(ISNUMBER(SEARCH(TEXT(E$11,"mm/dd/yyyy"), INDIRECT("'Data Murid'!$E" & ROW($E18)))), "✔", ""))} -> #REF! | F25: {=IF(OR(F$11="", INDIRECT("'Data Murid'!$E" & ROW($E18))=""), "", IF(ISNUMBER(SEARCH(TEXT(F$11,"mm/dd/yyyy"), INDIRECT("'Data Murid'!$E" & ROW($E18)))), "✔", ""))} -> #REF! | G25: {=IF(OR(G$11="", INDIRECT("'Data Murid'!$E" & ROW($E18))=""), "", IF(ISNUMBER(SEARCH(TEXT(G$11,"mm/dd/yyyy"), INDIRECT("'Data Murid'!$E" & ROW($E18)))), "✔", ""))} -> #REF! | H25: {=IF(OR(H$11="", INDIRECT("'Data Murid'!$E" & ROW($E18))=""), "", IF(ISNUMBER(SEARCH(TEXT(H$11,"mm/dd/yyyy"), INDIRECT("'Data Murid'!$E" & ROW($E18)))), "✔", ""))} -> #REF! | I25: {=IF(OR(I$11="", INDIRECT("'Data Murid'!$E" & ROW($E18))=""), "", IF(ISNUMBER(SEARCH(TEXT(I$11,"mm/dd/yyyy"), INDIRECT("'Data Murid'!$E" & ROW($E18)))), "✔", ""))} -> #REF! | J25: {=IF(OR(J$11="", INDIRECT("'Data Murid'!$E" & ROW($E18))=""), "", IF(ISNUMBER(SEARCH(TEXT(J$11,"mm/dd/yyyy"), INDIRECT("'Data Murid'!$E" & ROW($E18)))), "✔", ""))} -> #REF! | K25: {=IF(OR(K$11="", INDIRECT("'Data Murid'!$E" & ROW($E18))=""), "", IF(ISNUMBER(SEARCH(TEXT(K$11,"mm/dd/yyyy"), INDIRECT("'Data Murid'!$E" & ROW($E18)))), "✔", ""))} -> #REF! | L25: {=IF(OR(L$11="", INDIRECT("'Data Murid'!$E" & ROW($E18))=""), "", IF(ISNUMBER(SEARCH(TEXT(L$11,"mm/dd/yyyy"), INDIRECT("'Data Murid'!$E" & ROW($E18)))), "✔", ""))} -> #REF! | ... AI25: {=IF(OR(AI$11="", INDIRECT("'Data Murid'!$E" & ROW($E18))=""), "", IF(ISNUMBER(SEARCH(TEXT(AI$11,"mm/dd/yyyy"), INDIRECT("'Data Murid'!$E" & ROW($E18)))), "✔", ""))} -> #REF! | AJ25: =COUNTIF(E25:AI25, "✔") -> 0
A26: 12 | B26: ='rekap absensi seluruhnya'!B31 -> #REF! | C26: ='rekap absensi seluruhnya'!C31 -> #REF! | D26: ='rekap absensi seluruhnya'!D31 -> #REF! | E26: {=IF(OR(E$11="", INDIRECT("'Data Murid'!$E" & ROW($E19))=""), "", IF(ISNUMBER(SEARCH(TEXT(E$11,"mm/dd/yyyy"), INDIRECT("'Data Murid'!$E" & ROW($E19)))), "✔", ""))} -> #REF! | F26: {=IF(OR(F$11="", INDIRECT("'Data Murid'!$E" & ROW($E19))=""), "", IF(ISNUMBER(SEARCH(TEXT(F$11,"mm/dd/yyyy"), INDIRECT("'Data Murid'!$E" & ROW($E19)))), "✔", ""))} -> #REF! | G26: {=IF(OR(G$11="", INDIRECT("'Data Murid'!$E" & ROW($E19))=""), "", IF(ISNUMBER(SEARCH(TEXT(G$11,"mm/dd/yyyy"), INDIRECT("'Data Murid'!$E" & ROW($E19)))), "✔", ""))} -> #REF! | H26: {=IF(OR(H$11="", INDIRECT("'Data Murid'!$E" & ROW($E19))=""), "", IF(ISNUMBER(SEARCH(TEXT(H$11,"mm/dd/yyyy"), INDIRECT("'Data Murid'!$E" & ROW($E19)))), "✔", ""))} -> #REF! | I26: {=IF(OR(I$11="", INDIRECT("'Data Murid'!$E" & ROW($E19))=""), "", IF(ISNUMBER(SEARCH(TEXT(I$11,"mm/dd/yyyy"), INDIRECT("'Data Murid'!$E" & ROW($E19)))), "✔", ""))} -> #REF! | J26: {=IF(OR(J$11="", INDIRECT("'Data Murid'!$E" & ROW($E19))=""), "", IF(ISNUMBER(SEARCH(TEXT(J$11,"mm/dd/yyyy"), INDIRECT("'Data Murid'!$E" & ROW($E19)))), "✔", ""))} -> #REF! | K26: {=IF(OR(K$11="", INDIRECT("'Data Murid'!$E" & ROW($E19))=""), "", IF(ISNUMBER(SEARCH(TEXT(K$11,"mm/dd/yyyy"), INDIRECT("'Data Murid'!$E" & ROW($E19)))), "✔", ""))} -> #REF! | L26: {=IF(OR(L$11="", INDIRECT("'Data Murid'!$E" & ROW($E19))=""), "", IF(ISNUMBER(SEARCH(TEXT(L$11,"mm/dd/yyyy"), INDIRECT("'Data Murid'!$E" & ROW($E19)))), "✔", ""))} -> #REF! | ... AI26: {=IF(OR(AI$11="", INDIRECT("'Data Murid'!$E" & ROW($E19))=""), "", IF(ISNUMBER(SEARCH(TEXT(AI$11,"mm/dd/yyyy"), INDIRECT("'Data Murid'!$E" & ROW($E19)))), "✔", ""))} -> #REF! | AJ26: =COUNTIF(E26:AI26, "✔") -> 0
... A54: 40 | B54: ='rekap absensi seluruhnya'!B59 -> #REF! | C54: ='rekap absensi seluruhnya'!C59 -> #REF! | D54: ='rekap absensi seluruhnya'!D59 -> #REF! | E54: {=IF(OR(E$11="", INDIRECT("'Data Murid'!$E" & ROW($E47))=""), "", IF(ISNUMBER(SEARCH(TEXT(E$11,"mm/dd/yyyy"), INDIRECT("'Data Murid'!$E" & ROW($E47)))), "✔", ""))} -> #REF! | F54: {=IF(OR(F$11="", INDIRECT("'Data Murid'!$E" & ROW($E47))=""), "", IF(ISNUMBER(SEARCH(TEXT(F$11,"mm/dd/yyyy"), INDIRECT("'Data Murid'!$E" & ROW($E47)))), "✔", ""))} -> #REF! | G54: {=IF(OR(G$11="", INDIRECT("'Data Murid'!$E" & ROW($E47))=""), "", IF(ISNUMBER(SEARCH(TEXT(G$11,"mm/dd/yyyy"), INDIRECT("'Data Murid'!$E" & ROW($E47)))), "✔", ""))} -> #REF! | H54: {=IF(OR(H$11="", INDIRECT("'Data Murid'!$E" & ROW($E47))=""), "", IF(ISNUMBER(SEARCH(TEXT(H$11,"mm/dd/yyyy"), INDIRECT("'Data Murid'!$E" & ROW($E47)))), "✔", ""))} -> #REF! | I54: {=IF(OR(I$11="", INDIRECT("'Data Murid'!$E" & ROW($E47))=""), "", IF(ISNUMBER(SEARCH(TEXT(I$11,"mm/dd/yyyy"), INDIRECT("'Data Murid'!$E" & ROW($E47)))), "✔", ""))} -> #REF! | J54: {=IF(OR(J$11="", INDIRECT("'Data Murid'!$E" & ROW($E47))=""), "", IF(ISNUMBER(SEARCH(TEXT(J$11,"mm/dd/yyyy"), INDIRECT("'Data Murid'!$E" & ROW($E47)))), "✔", ""))} -> #REF! | K54: {=IF(OR(K$11="", INDIRECT("'Data Murid'!$E" & ROW($E47))=""), "", IF(ISNUMBER(SEARCH(TEXT(K$11,"mm/dd/yyyy"), INDIRECT("'Data Murid'!$E" & ROW($E47)))), "✔", ""))} -> #REF! | L54: {=IF(OR(L$11="", INDIRECT("'Data Murid'!$E" & ROW($E47))=""), "", IF(ISNUMBER(SEARCH(TEXT(L$11,"mm/dd/yyyy"), INDIRECT("'Data Murid'!$E" & ROW($E47)))), "✔", ""))} -> #REF! | ... AI54: {=IF(OR(AI$11="", INDIRECT("'Data Murid'!$E" & ROW($E47))=""), "", IF(ISNUMBER(SEARCH(TEXT(AI$11,"mm/dd/yyyy"), INDIRECT("'Data Murid'!$E" & ROW($E47)))), "✔", ""))} -> #REF! | AJ54: =COUNTIF(E54:AI54, "✔") -> 0

Sheet Ags
A1: PEMERINTAH PROVINSI JAWA TIMUR
A2: DINAS PENDIDIKAN
A3: SEKOLAH MENENGAH ATAS NEGERI 21 SURABAYA
A4: Jl. Argopuro 11-15 Surabaya Telp. 031-5350753 Fax. 031-5341530
A6: DAFTAR KETERLAMBATAN SISWA
A7: ='rekap absensi seluruhnya'!E7 -> #REF!
A9: NO | C9: NAMA LENGKAP | D9: JK | E9: PERTEMUAN TGL (ABSENSI) | AJ9: Total Keterlambatan
A11: Urut | B11: NIS | E11: =DATE(--LEFT(INDIRECT("'Data Murid'!A3"),4),8,1) -> #REF! | F11: =IF(MONTH(E11+1)=MONTH($E11), E11+1, "") -> #REF! | G11: =IF(MONTH(F11+1)=MONTH($E11), F11+1, "") -> #REF! | H11: =IF(MONTH(G11+1)=MONTH($E11), G11+1, "") -> #REF! | I11: =IF(MONTH(H11+1)=MONTH($E11), H11+1, "") -> #REF! | J11: =IF(MONTH(I11+1)=MONTH($E11), I11+1, "") -> #REF! | K11: =IF(MONTH(J11+1)=MONTH($E11), J11+1, "") -> #REF! | L11: =IF(MONTH(K11+1)=MONTH($E11), K11+1, "") -> #REF! | M11: =IF(MONTH(L11+1)=MONTH($E11), L11+1, "") -> #REF! | ... AI11: =IF(MONTH(AH11+1)=MONTH($E11), AH11+1, "") -> #REF!
E12: =IF(E11="","",TEXT(E11,"[$-id]ddd")) -> #REF! | F12: =IF(F11="","",TEXT(F11,"[$-id]ddd")) -> #REF! | G12: =IF(G11="","",TEXT(G11,"[$-id]ddd")) -> #REF! | H12: =IF(H11="","",TEXT(H11,"[$-id]ddd")) -> #REF! | I12: =IF(I11="","",TEXT(I11,"[$-id]ddd")) -> #REF! | J12: =IF(J11="","",TEXT(J11,"[$-id]ddd")) -> #REF! | K12: =IF(K11="","",TEXT(K11,"[$-id]ddd")) -> #REF! | L12: =IF(L11="","",TEXT(L11,"[$-id]ddd")) -> #REF! | ... AI12: =IF(AI11="","",TEXT(AI11,"[$-id]ddd")) -> #REF!
A14: ='rekap absensi seluruhnya'!A19:T19 -> #REF!
A15: 1 | B15: ='rekap absensi seluruhnya'!B20 -> #REF! | C15: ='rekap absensi seluruhnya'!C20 -> #REF! | D15: ='rekap absensi seluruhnya'!D20 -> #REF! | E15: {=IF(OR(E$11="", INDIRECT("'Data Murid'!$E" & ROW($E8))=""), "", IF(ISNUMBER(SEARCH(TEXT(E$11,"mm/dd/yyyy"), INDIRECT("'Data Murid'!$E" & ROW($E8)))), "✔", ""))} -> #REF! | F15: {=IF(OR(F$11="", INDIRECT("'Data Murid'!$E" & ROW($E8))=""), "", IF(ISNUMBER(SEARCH(TEXT(F$11,"mm/dd/yyyy"), INDIRECT("'Data Murid'!$E" & ROW($E8)))), "✔", ""))} -> #REF! | G15: {=IF(OR(G$11="", INDIRECT("'Data Murid'!$E" & ROW($E8))=""), "", IF(ISNUMBER(SEARCH(TEXT(G$11,"mm/dd/yyyy"), INDIRECT("'Data Murid'!$E" & ROW($E8)))), "✔", ""))} -> #REF! | H15: {=IF(OR(H$11="", INDIRECT("'Data Murid'!$E" & ROW($E8))=""), "", IF(ISNUMBER(SEARCH(TEXT(H$11,"mm/dd/yyyy"), INDIRECT("'Data Murid'!$E" & ROW($E8)))), "✔", ""))} -> #REF! | I15: {=IF(OR(I$11="", INDIRECT("'Data Murid'!$E" & ROW($E8))=""), "", IF(ISNUMBER(SEARCH(TEXT(I$11,"mm/dd/yyyy"), INDIRECT("'Data Murid'!$E" & ROW($E8)))), "✔", ""))} -> #REF! | J15: {=IF(OR(J$11="", INDIRECT("'Data Murid'!$E" & ROW($E8))=""), "", IF(ISNUMBER(SEARCH(TEXT(J$11,"mm/dd/yyyy"), INDIRECT("'Data Murid'!$E" & ROW($E8)))), "✔", ""))} -> #REF! | K15: {=IF(OR(K$11="", INDIRECT("'Data Murid'!$E" & ROW($E8))=""), "", IF(ISNUMBER(SEARCH(TEXT(K$11,"mm/dd/yyyy"), INDIRECT("'Data Murid'!$E" & ROW($E8)))), "✔", ""))} -> #REF! | L15: {=IF(OR(L$11="", INDIRECT("'Data Murid'!$E" & ROW($E8))=""), "", IF(ISNUMBER(SEARCH(TEXT(L$11,"mm/dd/yyyy"), INDIRECT("'Data Murid'!$E" & ROW($E8)))), "✔", ""))} -> #REF! | ... AI15: {=IF(OR(AI$11="", INDIRECT("'Data Murid'!$E" & ROW($E8))=""), "", IF(ISNUMBER(SEARCH(TEXT(AI$11,"mm/dd/yyyy"), INDIRECT("'Data Murid'!$E" & ROW($E8)))), "✔", ""))} -> #REF! | AJ15: =COUNTIF(E15:AI15, "✔") -> 0
A16: 2 | B16: ='rekap absensi seluruhnya'!B21 -> #REF! | C16: ='rekap absensi seluruhnya'!C21 -> #REF! | D16: ='rekap absensi seluruhnya'!D21 -> #REF! | E16: {=IF(OR(E$11="", INDIRECT("'Data Murid'!$E" & ROW($E9))=""), "", IF(ISNUMBER(SEARCH(TEXT(E$11,"mm/dd/yyyy"), INDIRECT("'Data Murid'!$E" & ROW($E9)))), "✔", ""))} -> #REF! | F16: {=IF(OR(F$11="", INDIRECT("'Data Murid'!$E" & ROW($E9))=""), "", IF(ISNUMBER(SEARCH(TEXT(F$11,"mm/dd/yyyy"), INDIRECT("'Data Murid'!$E" & ROW($E9)))), "✔", ""))} -> #REF! | G16: {=IF(OR(G$11="", INDIRECT("'Data Murid'!$E" & ROW($E9))=""), "", IF(ISNUMBER(SEARCH(TEXT(G$11,"mm/dd/yyyy"), INDIRECT("'Data Murid'!$E" & ROW($E9)))), "✔", ""))} -> #REF! | H16: {=IF(OR(H$11="", INDIRECT("'Data Murid'!$E" & ROW($E9))=""), "", IF(ISNUMBER(SEARCH(TEXT(H$11,"mm/dd/yyyy"), INDIRECT("'Data Murid'!$E" & ROW($E9)))), "✔", ""))} -> #REF! | I16: {=IF(OR(I$11="", INDIRECT("'Data Murid'!$E" & ROW($E9))=""), "", IF(ISNUMBER(SEARCH(TEXT(I$11,"mm/dd/yyyy"), INDIRECT("'Data Murid'!$E" & ROW($E9)))), "✔", ""))} -> #REF! | J16: {=IF(OR(J$11="", INDIRECT("'Data Murid'!$E" & ROW($E9))=""), "", IF(ISNUMBER(SEARCH(TEXT(J$11,"mm/dd/yyyy"), INDIRECT("'Data Murid'!$E" & ROW($E9)))), "✔", ""))} -> #REF! | K16: {=IF(OR(K$11="", INDIRECT("'Data Murid'!$E" & ROW($E9))=""), "", IF(ISNUMBER(SEARCH(TEXT(K$11,"mm/dd/yyyy"), INDIRECT("'Data Murid'!$E" & ROW($E9)))), "✔", ""))} -> #REF! | L16: {=IF(OR(L$11="", INDIRECT("'Data Murid'!$E" & ROW($E9))=""), "", IF(ISNUMBER(SEARCH(TEXT(L$11,"mm/dd/yyyy"), INDIRECT("'Data Murid'!$E" & ROW($E9)))), "✔", ""))} -> #REF! | ... AI16: {=IF(OR(AI$11="", INDIRECT("'Data Murid'!$E" & ROW($E9))=""), "", IF(ISNUMBER(SEARCH(TEXT(AI$11,"mm/dd/yyyy"), INDIRECT("'Data Murid'!$E" & ROW($E9)))), "✔", ""))} -> #REF! | AJ16: =COUNTIF(E16:AI16, "✔") -> 0
A17: 3 | B17: ='rekap absensi seluruhnya'!B22 -> #REF! | C17: ='rekap absensi seluruhnya'!C22 -> #REF! | D17: ='rekap absensi seluruhnya'!D22 -> #REF! | E17: {=IF(OR(E$11="", INDIRECT("'Data Murid'!$E" & ROW($E10))=""), "", IF(ISNUMBER(SEARCH(TEXT(E$11,"mm/dd/yyyy"), INDIRECT("'Data Murid'!$E" & ROW($E10)))), "✔", ""))} -> #REF! | F17: {=IF(OR(F$11="", INDIRECT("'Data Murid'!$E" & ROW($E10))=""), "", IF(ISNUMBER(SEARCH(TEXT(F$11,"mm/dd/yyyy"), INDIRECT("'Data Murid'!$E" & ROW($E10)))), "✔", ""))} -> #REF! | G17: {=IF(OR(G$11="", INDIRECT("'Data Murid'!$E" & ROW($E10))=""), "", IF(ISNUMBER(SEARCH(TEXT(G$11,"mm/dd/yyyy"), INDIRECT("'Data Murid'!$E" & ROW($E10)))), "✔", ""))} -> #REF! | H17: {=IF(OR(H$11="", INDIRECT("'Data Murid'!$E" & ROW($E10))=""), "", IF(ISNUMBER(SEARCH(TEXT(H$11,"mm/dd/yyyy"), INDIRECT("'Data Murid'!$E" & ROW($E10)))), "✔", ""))} -> #REF! | I17: {=IF(OR(I$11="", INDIRECT("'Data Murid'!$E" & ROW($E10))=""), "", IF(ISNUMBER(SEARCH(TEXT(I$11,"mm/dd/yyyy"), INDIRECT("'Data Murid'!$E" & ROW($E10)))), "✔", ""))} -> #REF! | J17: {=IF(OR(J$11="", INDIRECT("'Data Murid'!$E" & ROW($E10))=""), "", IF(ISNUMBER(SEARCH(TEXT(J$11,"mm/dd/yyyy"), INDIRECT("'Data Murid'!$E" & ROW($E10)))), "✔", ""))} -> #REF! | K17: {=IF(OR(K$11="", INDIRECT("'Data Murid'!$E" & ROW($E10))=""), "", IF(ISNUMBER(SEARCH(TEXT(K$11,"mm/dd/yyyy"), INDIRECT("'Data Murid'!$E" & ROW($E10)))), "✔", ""))} -> #REF! | L17: {=IF(OR(L$11="", INDIRECT("'Data Murid'!$E" & ROW($E10))=""), "", IF(ISNUMBER(SEARCH(TEXT(L$11,"mm/dd/yyyy"), INDIRECT("'Data Murid'!$E" & ROW($E10)))), "✔", ""))} -> #REF! | ... AI17: {=IF(OR(AI$11="", INDIRECT("'Data Murid'!$E" & ROW($E10))=""), "", IF(ISNUMBER(SEARCH(TEXT(AI$11,"mm/dd/yyyy"), INDIRECT("'Data Murid'!$E" & ROW($E10)))), "✔", ""))} -> #REF! | AJ17: =COUNTIF(E17:AI17, "✔") -> 0
A18: 4 | B18: ='rekap absensi seluruhnya'!B23 -> #REF! | C18: ='rekap absensi seluruhnya'!C23 -> #REF! | D18: ='rekap absensi seluruhnya'!D23 -> #REF! | E18: {=IF(OR(E$11="", INDIRECT("'Data Murid'!$E" & ROW($E11))=""), "", IF(ISNUMBER(SEARCH(TEXT(E$11,"mm/dd/yyyy"), INDIRECT("'Data Murid'!$E" & ROW($E11)))), "✔", ""))} -> #REF! | F18: {=IF(OR(F$11="", INDIRECT("'Data Murid'!$E" & ROW($E11))=""), "", IF(ISNUMBER(SEARCH(TEXT(F$11,"mm/dd/yyyy"), INDIRECT("'Data Murid'!$E" & ROW($E11)))), "✔", ""))} -> #REF! | G18: {=IF(OR(G$11="", INDIRECT("'Data Murid'!$E" & ROW($E11))=""), "", IF(ISNUMBER(SEARCH(TEXT(G$11,"mm/dd/yyyy"), INDIRECT("'Data Murid'!$E" & ROW($E11)))), "✔", ""))} -> #REF! | H18: {=IF(OR(H$11="", INDIRECT("'Data Murid'!$E" & ROW($E11))=""), "", IF(ISNUMBER(SEARCH(TEXT(H$11,"mm/dd/yyyy"), INDIRECT("'Data Murid'!$E" & ROW($E11)))), "✔", ""))} -> #REF! | I18: {=IF(OR(I$11="", INDIRECT("'Data Murid'!$E" & ROW($E11))=""), "", IF(ISNUMBER(SEARCH(TEXT(I$11,"mm/dd/yyyy"), INDIRECT("'Data Murid'!$E" & ROW($E11)))), "✔", ""))} -> #REF! | J18: {=IF(OR(J$11="", INDIRECT("'Data Murid'!$E" & ROW($E11))=""), "", IF(ISNUMBER(SEARCH(TEXT(J$11,"mm/dd/yyyy"), INDIRECT("'Data Murid'!$E" & ROW($E11)))), "✔", ""))} -> #REF! | K18: {=IF(OR(K$11="", INDIRECT("'Data Murid'!$E" & ROW($E11))=""), "", IF(ISNUMBER(SEARCH(TEXT(K$11,"mm/dd/yyyy"), INDIRECT("'Data Murid'!$E" & ROW($E11)))), "✔", ""))} -> #REF! | L18: {=IF(OR(L$11="", INDIRECT("'Data Murid'!$E" & ROW($E11))=""), "", IF(ISNUMBER(SEARCH(TEXT(L$11,"mm/dd/yyyy"), INDIRECT("'Data Murid'!$E" & ROW($E11)))), "✔", ""))} -> #REF! | ... AI18: {=IF(OR(AI$11="", INDIRECT("'Data Murid'!$E" & ROW($E11))=""), "", IF(ISNUMBER(SEARCH(TEXT(AI$11,"mm/dd/yyyy"), INDIRECT("'Data Murid'!$E" & ROW($E11)))), "✔", ""))} -> #REF! | AJ18: =COUNTIF(E18:AI18, "✔") -> 0
A19: 5 | B19: ='rekap absensi seluruhnya'!B24 -> #REF! | C19: ='rekap absensi seluruhnya'!C24 -> #REF! | D19: ='rekap absensi seluruhnya'!D24 -> #REF! | E19: {=IF(OR(E$11="", INDIRECT("'Data Murid'!$E" & ROW($E12))=""), "", IF(ISNUMBER(SEARCH(TEXT(E$11,"mm/dd/yyyy"), INDIRECT("'Data Murid'!$E" & ROW($E12)))), "✔", ""))} -> #REF! | F19: {=IF(OR(F$11="", INDIRECT("'Data Murid'!$E" & ROW($E12))=""), "", IF(ISNUMBER(SEARCH(TEXT(F$11,"mm/dd/yyyy"), INDIRECT("'Data Murid'!$E" & ROW($E12)))), "✔", ""))} -> #REF! | G19: {=IF(OR(G$11="", INDIRECT("'Data Murid'!$E" & ROW($E12))=""), "", IF(ISNUMBER(SEARCH(TEXT(G$11,"mm/dd/yyyy"), INDIRECT("'Data Murid'!$E" & ROW($E12)))), "✔", ""))} -> #REF! | H19: {=IF(OR(H$11="", INDIRECT("'Data Murid'!$E" & ROW($E12))=""), "", IF(ISNUMBER(SEARCH(TEXT(H$11,"mm/dd/yyyy"), INDIRECT("'Data Murid'!$E" & ROW($E12)))), "✔", ""))} -> #REF! | I19: {=IF(OR(I$11="", INDIRECT("'Data Murid'!$E" & ROW($E12))=""), "", IF(ISNUMBER(SEARCH(TEXT(I$11,"mm/dd/yyyy"), INDIRECT("'Data Murid'!$E" & ROW($E12)))), "✔", ""))} -> #REF! | J19: {=IF(OR(J$11="", INDIRECT("'Data Murid'!$E" & ROW($E12))=""), "", IF(ISNUMBER(SEARCH(TEXT(J$11,"mm/dd/yyyy"), INDIRECT("'Data Murid'!$E" & ROW($E12)))), "✔", ""))} -> #REF! | K19: {=IF(OR(K$11="", INDIRECT("'Data Murid'!$E" & ROW($E12))=""), "", IF(ISNUMBER(SEARCH(TEXT(K$11,"mm/dd/yyyy"), INDIRECT("'Data Murid'!$E" & ROW($E12)))), "✔", ""))} -> #REF! | L19: {=IF(OR(L$11="", INDIRECT("'Data Murid'!$E" & ROW($E12))=""), "", IF(ISNUMBER(SEARCH(TEXT(L$11,"mm/dd/yyyy"), INDIRECT("'Data Murid'!$E" & ROW($E12)))), "✔", ""))} -> #REF! | ... AI19: {=IF(OR(AI$11="", INDIRECT("'Data Murid'!$E" & ROW($E12))=""), "", IF(ISNUMBER(SEARCH(TEXT(AI$11,"mm/dd/yyyy"), INDIRECT("'Data Murid'!$E" & ROW($E12)))), "✔", ""))} -> #REF! | AJ19: =COUNTIF(E19:AI19, "✔") -> 0
A20: 6 | B20: ='rekap absensi seluruhnya'!B25 -> #REF! | C20: ='rekap absensi seluruhnya'!C25 -> #REF! | D20: ='rekap absensi seluruhnya'!D25 -> #REF! | E20: {=IF(OR(E$11="", INDIRECT("'Data Murid'!$E" & ROW($E13))=""), "", IF(ISNUMBER(SEARCH(TEXT(E$11,"mm/dd/yyyy"), INDIRECT("'Data Murid'!$E" & ROW($E13)))), "✔", ""))} -> #REF! | F20: {=IF(OR(F$11="", INDIRECT("'Data Murid'!$E" & ROW($E13))=""), "", IF(ISNUMBER(SEARCH(TEXT(F$11,"mm/dd/yyyy"), INDIRECT("'Data Murid'!$E" & ROW($E13)))), "✔", ""))} -> #REF! | G20: {=IF(OR(G$11="", INDIRECT("'Data Murid'!$E" & ROW($E13))=""), "", IF(ISNUMBER(SEARCH(TEXT(G$11,"mm/dd/yyyy"), INDIRECT("'Data Murid'!$E" & ROW($E13)))), "✔", ""))} -> #REF! | H20: {=IF(OR(H$11="", INDIRECT("'Data Murid'!$E" & ROW($E13))=""), "", IF(ISNUMBER(SEARCH(TEXT(H$11,"mm/dd/yyyy"), INDIRECT("'Data Murid'!$E" & ROW($E13)))), "✔", ""))} -> #REF! | I20: {=IF(OR(I$11="", INDIRECT("'Data Murid'!$E" & ROW($E13))=""), "", IF(ISNUMBER(SEARCH(TEXT(I$11,"mm/dd/yyyy"), INDIRECT("'Data Murid'!$E" & ROW($E13)))), "✔", ""))} -> #REF! | J20: {=IF(OR(J$11="", INDIRECT("'Data Murid'!$E" & ROW($E13))=""), "", IF(ISNUMBER(SEARCH(TEXT(J$11,"mm/dd/yyyy"), INDIRECT("'Data Murid'!$E" & ROW($E13)))), "✔", ""))} -> #REF! | K20: {=IF(OR(K$11="", INDIRECT("'Data Murid'!$E" & ROW($E13))=""), "", IF(ISNUMBER(SEARCH(TEXT(K$11,"mm/dd/yyyy"), INDIRECT("'Data Murid'!$E" & ROW($E13)))), "✔", ""))} -> #REF! | L20: {=IF(OR(L$11="", INDIRECT("'Data Murid'!$E" & ROW($E13))=""), "", IF(ISNUMBER(SEARCH(TEXT(L$11,"mm/dd/yyyy"), INDIRECT("'Data Murid'!$E" & ROW($E13)))), "✔", ""))} -> #REF! | ... AI20: {=IF(OR(AI$11="", INDIRECT("'Data Murid'!$E" & ROW($E13))=""), "", IF(ISNUMBER(SEARCH(TEXT(AI$11,"mm/dd/yyyy"), INDIRECT("'Data Murid'!$E" & ROW($E13)))), "✔", ""))} -> #REF! | AJ20: =COUNTIF(E20:AI20, "✔") -> 0
A21: 7 | B21: ='rekap absensi seluruhnya'!B26 -> #REF! | C21: ='rekap absensi seluruhnya'!C26 -> #REF! | D21: ='rekap absensi seluruhnya'!D26 -> #REF! | E21: {=IF(OR(E$11="", INDIRECT("'Data Murid'!$E" & ROW($E14))=""), "", IF(ISNUMBER(SEARCH(TEXT(E$11,"mm/dd/yyyy"), INDIRECT("'Data Murid'!$E" & ROW($E14)))), "✔", ""))} -> #REF! | F21: {=IF(OR(F$11="", INDIRECT("'Data Murid'!$E" & ROW($E14))=""), "", IF(ISNUMBER(SEARCH(TEXT(F$11,"mm/dd/yyyy"), INDIRECT("'Data Murid'!$E" & ROW($E14)))), "✔", ""))} -> #REF! | G21: {=IF(OR(G$11="", INDIRECT("'Data Murid'!$E" & ROW($E14))=""), "", IF(ISNUMBER(SEARCH(TEXT(G$11,"mm/dd/yyyy"), INDIRECT("'Data Murid'!$E" & ROW($E14)))), "✔", ""))} -> #REF! | H21: {=IF(OR(H$11="", INDIRECT("'Data Murid'!$E" & ROW($E14))=""), "", IF(ISNUMBER(SEARCH(TEXT(H$11,"mm/dd/yyyy"), INDIRECT("'Data Murid'!$E" & ROW($E14)))), "✔", ""))} -> #REF! | I21: {=IF(OR(I$11="", INDIRECT("'Data Murid'!$E" & ROW($E14))=""), "", IF(ISNUMBER(SEARCH(TEXT(I$11,"mm/dd/yyyy"), INDIRECT("'Data Murid'!$E" & ROW($E14)))), "✔", ""))} -> #REF! | J21: {=IF(OR(J$11="", INDIRECT("'Data Murid'!$E" & ROW($E14))=""), "", IF(ISNUMBER(SEARCH(TEXT(J$11,"mm/dd/yyyy"), INDIRECT("'Data Murid'!$E" & ROW($E14)))), "✔", ""))} -> #REF! | K21: {=IF(OR(K$11="", INDIRECT("'Data Murid'!$E" & ROW($E14))=""), "", IF(ISNUMBER(SEARCH(TEXT(K$11,"mm/dd/yyyy"), INDIRECT("'Data Murid'!$E" & ROW($E14)))), "✔", ""))} -> #REF! | L21: {=IF(OR(L$11="", INDIRECT("'Data Murid'!$E" & ROW($E14))=""), "", IF(ISNUMBER(SEARCH(TEXT(L$11,"mm/dd/yyyy"), INDIRECT("'Data Murid'!$E" & ROW($E14)))), "✔", ""))} -> #REF! | ... AI21: {=IF(OR(AI$11="", INDIRECT("'Data Murid'!$E" & ROW($E14))=""), "", IF(ISNUMBER(SEARCH(TEXT(AI$11,"mm/dd/yyyy"), INDIRECT("'Data Murid'!$E" & ROW($E14)))), "✔", ""))} -> #REF! | AJ21: =COUNTIF(E21:AI21, "✔") -> 0
A22: 8 | B22: ='rekap absensi seluruhnya'!B27 -> #REF! | C22: ='rekap absensi seluruhnya'!C27 -> #REF! | D22: ='rekap absensi seluruhnya'!D27 -> #REF! | E22: {=IF(OR(E$11="", INDIRECT("'Data Murid'!$E" & ROW($E15))=""), "", IF(ISNUMBER(SEARCH(TEXT(E$11,"mm/dd/yyyy"), INDIRECT("'Data Murid'!$E" & ROW($E15)))), "✔", ""))} -> #REF! | F22: {=IF(OR(F$11="", INDIRECT("'Data Murid'!$E" & ROW($E15))=""), "", IF(ISNUMBER(SEARCH(TEXT(F$11,"mm/dd/yyyy"), INDIRECT("'Data Murid'!$E" & ROW($E15)))), "✔", ""))} -> #REF! | G22: {=IF(OR(G$11="", INDIRECT("'Data Murid'!$E" & ROW($E15))=""), "", IF(ISNUMBER(SEARCH(TEXT(G$11,"mm/dd/yyyy"), INDIRECT("'Data Murid'!$E" & ROW($E15)))), "✔", ""))} -> #REF! | H22: {=IF(OR(H$11="", INDIRECT("'Data Murid'!$E" & ROW($E15))=""), "", IF(ISNUMBER(SEARCH(TEXT(H$11,"mm/dd/yyyy"), INDIRECT("'Data Murid'!$E" & ROW($E15)))), "✔", ""))} -> #REF! | I22: {=IF(OR(I$11="", INDIRECT("'Data Murid'!$E" & ROW($E15))=""), "", IF(ISNUMBER(SEARCH(TEXT(I$11,"mm/dd/yyyy"), INDIRECT("'Data Murid'!$E" & ROW($E15)))), "✔", ""))} -> #REF! | J22: {=IF(OR(J$11="", INDIRECT("'Data Murid'!$E" & ROW($E15))=""), "", IF(ISNUMBER(SEARCH(TEXT(J$11,"mm/dd/yyyy"), INDIRECT("'Data Murid'!$E" & ROW($E15)))), "✔", ""))} -> #REF! | K22: {=IF(OR(K$11="", INDIRECT("'Data Murid'!$E" & ROW($E15))=""), "", IF(ISNUMBER(SEARCH(TEXT(K$11,"mm/dd/yyyy"), INDIRECT("'Data Murid'!$E" & ROW($E15)))), "✔", ""))} -> #REF! | L22: {=IF(OR(L$11="", INDIRECT("'Data Murid'!$E" & ROW($E15))=""), "", IF(ISNUMBER(SEARCH(TEXT(L$11,"mm/dd/yyyy"), INDIRECT("'Data Murid'!$E" & ROW($E15)))), "✔", ""))} -> #REF! | ... AI22: {=IF(OR(AI$11="", INDIRECT("'Data Murid'!$E" & ROW($E15))=""), "", IF(ISNUMBER(SEARCH(TEXT(AI$11,"mm/dd/yyyy"), INDIRECT("'Data Murid'!$E" & ROW($E15)))), "✔", ""))} -> #REF! | AJ22: =COUNTIF(E22:AI22, "✔") -> 0
A23: 9 | B23: ='rekap absensi seluruhnya'!B28 -> #REF! | C23: ='rekap absensi seluruhnya'!C28 -> #REF! | D23: ='rekap absensi seluruhnya'!D28 -> #REF! | E23: {=IF(OR(E$11="", INDIRECT("'Data Murid'!$E" & ROW($E16))=""), "", IF(ISNUMBER(SEARCH(TEXT(E$11,"mm/dd/yyyy"), INDIRECT("'Data Murid'!$E" & ROW($E16)))), "✔", ""))} -> #REF! | F23: {=IF(OR(F$11="", INDIRECT("'Data Murid'!$E" & ROW($E16))=""), "", IF(ISNUMBER(SEARCH(TEXT(F$11,"mm/dd/yyyy"), INDIRECT("'Data Murid'!$E" & ROW($E16)))), "✔", ""))} -> #REF! | G23: {=IF(OR(G$11="", INDIRECT("'Data Murid'!$E" & ROW($E16))=""), "", IF(ISNUMBER(SEARCH(TEXT(G$11,"mm/dd/yyyy"), INDIRECT("'Data Murid'!$E" & ROW($E16)))), "✔", ""))} -> #REF! | H23: {=IF(OR(H$11="", INDIRECT("'Data Murid'!$E" & ROW($E16))=""), "", IF(ISNUMBER(SEARCH(TEXT(H$11,"mm/dd/yyyy"), INDIRECT("'Data Murid'!$E" & ROW($E16)))), "✔", ""))} -> #REF! | I23: {=IF(OR(I$11="", INDIRECT("'Data Murid'!$E" & ROW($E16))=""), "", IF(ISNUMBER(SEARCH(TEXT(I$11,"mm/dd/yyyy"), INDIRECT("'Data Murid'!$E" & ROW($E16)))), "✔", ""))} -> #REF! | J23: {=IF(OR(J$11="", INDIRECT("'Data Murid'!$E" & ROW($E16))=""), "", IF(ISNUMBER(SEARCH(TEXT(J$11,"mm/dd/yyyy"), INDIRECT("'Data Murid'!$E" & ROW($E16)))), "✔", ""))} -> #REF! | K23: {=IF(OR(K$11="", INDIRECT("'Data Murid'!$E" & ROW($E16))=""), "", IF(ISNUMBER(SEARCH(TEXT(K$11,"mm/dd/yyyy"), INDIRECT("'Data Murid'!$E" & ROW($E16)))), "✔", ""))} -> #REF! | L23: {=IF(OR(L$11="", INDIRECT("'Data Murid'!$E" & ROW($E16))=""), "", IF(ISNUMBER(SEARCH(TEXT(L$11,"mm/dd/yyyy"), INDIRECT("'Data Murid'!$E" & ROW($E16)))), "✔", ""))} -> #REF! | ... AI23: {=IF(OR(AI$11="", INDIRECT("'Data Murid'!$E" & ROW($E16))=""), "", IF(ISNUMBER(SEARCH(TEXT(AI$11,"mm/dd/yyyy"), INDIRECT("'Data Murid'!$E" & ROW($E16)))), "✔", ""))} -> #REF! | AJ23: =COUNTIF(E23:AI23, "✔") -> 0
A24: 10 | B24: ='rekap absensi seluruhnya'!B29 -> #REF! | C24: ='rekap absensi seluruhnya'!C29 -> #REF! | D24: ='rekap absensi seluruhnya'!D29 -> #REF! | E24: {=IF(OR(E$11="", INDIRECT("'Data Murid'!$E" & ROW($E17))=""), "", IF(ISNUMBER(SEARCH(TEXT(E$11,"mm/dd/yyyy"), INDIRECT("'Data Murid'!$E" & ROW($E17)))), "✔", ""))} -> #REF! | F24: {=IF(OR(F$11="", INDIRECT("'Data Murid'!$E" & ROW($E17))=""), "", IF(ISNUMBER(SEARCH(TEXT(F$11,"mm/dd/yyyy"), INDIRECT("'Data Murid'!$E" & ROW($E17)))), "✔", ""))} -> #REF! | G24: {=IF(OR(G$11="", INDIRECT("'Data Murid'!$E" & ROW($E17))=""), "", IF(ISNUMBER(SEARCH(TEXT(G$11,"mm/dd/yyyy"), INDIRECT("'Data Murid'!$E" & ROW($E17)))), "✔", ""))} -> #REF! | H24: {=IF(OR(H$11="", INDIRECT("'Data Murid'!$E" & ROW($E17))=""), "", IF(ISNUMBER(SEARCH(TEXT(H$11,"mm/dd/yyyy"), INDIRECT("'Data Murid'!$E" & ROW($E17)))), "✔", ""))} -> #REF! | I24: {=IF(OR(I$11="", INDIRECT("'Data Murid'!$E" & ROW($E17))=""), "", IF(ISNUMBER(SEARCH(TEXT(I$11,"mm/dd/yyyy"), INDIRECT("'Data Murid'!$E" & ROW($E17)))), "✔", ""))} -> #REF! | J24: {=IF(OR(J$11="", INDIRECT("'Data Murid'!$E" & ROW($E17))=""), "", IF(ISNUMBER(SEARCH(TEXT(J$11,"mm/dd/yyyy"), INDIRECT("'Data Murid'!$E" & ROW($E17)))), "✔", ""))} -> #REF! | K24: {=IF(OR(K$11="", INDIRECT("'Data Murid'!$E" & ROW($E17))=""), "", IF(ISNUMBER(SEARCH(TEXT(K$11,"mm/dd/yyyy"), INDIRECT("'Data Murid'!$E" & ROW($E17)))), "✔", ""))} -> #REF! | L24: {=IF(OR(L$11="", INDIRECT("'Data Murid'!$E" & ROW($E17))=""), "", IF(ISNUMBER(SEARCH(TEXT(L$11,"mm/dd/yyyy"), INDIRECT("'Data Murid'!$E" & ROW($E17)))), "✔", ""))} -> #REF! | ... AI24: {=IF(OR(AI$11="", INDIRECT("'Data Murid'!$E" & ROW($E17))=""), "", IF(ISNUMBER(SEARCH(TEXT(AI$11,"mm/dd/yyyy"), INDIRECT("'Data Murid'!$E" & ROW($E17)))), "✔", ""))} -> #REF! | AJ24: =COUNTIF(E24:AI24, "✔") -> 0
A25: 11 | B25: ='rekap absensi seluruhnya'!B30 -> #REF! | C25: ='rekap absensi seluruhnya'!C30 -> #REF! | D25: ='rekap absensi seluruhnya'!D30 -> #REF! | E25: {=IF(OR(E$11="", INDIRECT("'Data Murid'!$E" & ROW($E18))=""), "", IF(ISNUMBER(SEARCH(TEXT(E$11,"mm/dd/yyyy"), INDIRECT("'Data Murid'!$E" & ROW($E18)))), "✔", ""))} -> #REF! | F25: {=IF(OR(F$11="", INDIRECT("'Data Murid'!$E" & ROW($E18))=""), "", IF(ISNUMBER(SEARCH(TEXT(F$11,"mm/dd/yyyy"), INDIRECT("'Data Murid'!$E" & ROW($E18)))), "✔", ""))} -> #REF! | G25: {=IF(OR(G$11="", INDIRECT("'Data Murid'!$E" & ROW($E18))=""), "", IF(ISNUMBER(SEARCH(TEXT(G$11,"mm/dd/yyyy"), INDIRECT("'Data Murid'!$E" & ROW($E18)))), "✔", ""))} -> #REF! | H25: {=IF(OR(H$11="", INDIRECT("'Data Murid'!$E" & ROW($E18))=""), "", IF(ISNUMBER(SEARCH(TEXT(H$11,"mm/dd/yyyy"), INDIRECT("'Data Murid'!$E" & ROW($E18)))), "✔", ""))} -> #REF! | I25: {=IF(OR(I$11="", INDIRECT("'Data Murid'!$E" & ROW($E18))=""), "", IF(ISNUMBER(SEARCH(TEXT(I$11,"mm/dd/yyyy"), INDIRECT("'Data Murid'!$E" & ROW($E18)))), "✔", ""))} -> #REF! | J25: {=IF(OR(J$11="", INDIRECT("'Data Murid'!$E" & ROW($E18))=""), "", IF(ISNUMBER(SEARCH(TEXT(J$11,"mm/dd/yyyy"), INDIRECT("'Data Murid'!$E" & ROW($E18)))), "✔", ""))} -> #REF! | K25: {=IF(OR(K$11="", INDIRECT("'Data Murid'!$E" & ROW($E18))=""), "", IF(ISNUMBER(SEARCH(TEXT(K$11,"mm/dd/yyyy"), INDIRECT("'Data Murid'!$E" & ROW($E18)))), "✔", ""))} -> #REF! | L25: {=IF(OR(L$11="", INDIRECT("'Data Murid'!$E" & ROW($E18))=""), "", IF(ISNUMBER(SEARCH(TEXT(L$11,"mm/dd/yyyy"), INDIRECT("'Data Murid'!$E" & ROW($E18)))), "✔", ""))} -> #REF! | ... AI25: {=IF(OR(AI$11="", INDIRECT("'Data Murid'!$E" & ROW($E18))=""), "", IF(ISNUMBER(SEARCH(TEXT(AI$11,"mm/dd/yyyy"), INDIRECT("'Data Murid'!$E" & ROW($E18)))), "✔", ""))} -> #REF! | AJ25: =COUNTIF(E25:AI25, "✔") -> 0
A26: 12 | B26: ='rekap absensi seluruhnya'!B31 -> #REF! | C26: ='rekap absensi seluruhnya'!C31 -> #REF! | D26: ='rekap absensi seluruhnya'!D31 -> #REF! | E26: {=IF(OR(E$11="", INDIRECT("'Data Murid'!$E" & ROW($E19))=""), "", IF(ISNUMBER(SEARCH(TEXT(E$11,"mm/dd/yyyy"), INDIRECT("'Data Murid'!$E" & ROW($E19)))), "✔", ""))} -> #REF! | F26: {=IF(OR(F$11="", INDIRECT("'Data Murid'!$E" & ROW($E19))=""), "", IF(ISNUMBER(SEARCH(TEXT(F$11,"mm/dd/yyyy"), INDIRECT("'Data Murid'!$E" & ROW($E19)))), "✔", ""))} -> #REF! | G26: {=IF(OR(G$11="", INDIRECT("'Data Murid'!$E" & ROW($E19))=""), "", IF(ISNUMBER(SEARCH(TEXT(G$11,"mm/dd/yyyy"), INDIRECT("'Data Murid'!$E" & ROW($E19)))), "✔", ""))} -> #REF! | H26: {=IF(OR(H$11="", INDIRECT("'Data Murid'!$E" & ROW($E19))=""), "", IF(ISNUMBER(SEARCH(TEXT(H$11,"mm/dd/yyyy"), INDIRECT("'Data Murid'!$E" & ROW($E19)))), "✔", ""))} -> #REF! | I26: {=IF(OR(I$11="", INDIRECT("'Data Murid'!$E" & ROW($E19))=""), "", IF(ISNUMBER(SEARCH(TEXT(I$11,"mm/dd/yyyy"), INDIRECT("'Data Murid'!$E" & ROW($E19)))), "✔", ""))} -> #REF! | J26: {=IF(OR(J$11="", INDIRECT("'Data Murid'!$E" & ROW($E19))=""), "", IF(ISNUMBER(SEARCH(TEXT(J$11,"mm/dd/yyyy"), INDIRECT("'Data Murid'!$E" & ROW($E19)))), "✔", ""))} -> #REF! | K26: {=IF(OR(K$11="", INDIRECT("'Data Murid'!$E" & ROW($E19))=""), "", IF(ISNUMBER(SEARCH(TEXT(K$11,"mm/dd/yyyy"), INDIRECT("'Data Murid'!$E" & ROW($E19)))), "✔", ""))} -> #REF! | L26: {=IF(OR(L$11="", INDIRECT("'Data Murid'!$E" & ROW($E19))=""), "", IF(ISNUMBER(SEARCH(TEXT(L$11,"mm/dd/yyyy"), INDIRECT("'Data Murid'!$E" & ROW($E19)))), "✔", ""))} -> #REF! | ... AI26: {=IF(OR(AI$11="", INDIRECT("'Data Murid'!$E" & ROW($E19))=""), "", IF(ISNUMBER(SEARCH(TEXT(AI$11,"mm/dd/yyyy"), INDIRECT("'Data Murid'!$E" & ROW($E19)))), "✔", ""))} -> #REF! | AJ26: =COUNTIF(E26:AI26, "✔") -> 0
